Traceback (most recent call last):
  File "/home/users/jaeminoh/.conda/envs/PINNs/lib/python3.12/site-packages/jupyter_cache/executors/utils.py", line 58, in single_nb_execution
    executenb(
  File "/home/users/jaeminoh/.conda/envs/PINNs/lib/python3.12/site-packages/nbclient/client.py", line 1314, in execute
    return NotebookClient(nb=nb, resources=resources, km=km, **kwargs).execute()
           ^^^^^^^^^^^^^^^^^^^^^^^^^^^^^^^^^^^^^^^^^^^^^^^^^^^^^^^^^^^^^^^^^^^^^
  File "/home/users/jaeminoh/.conda/envs/PINNs/lib/python3.12/site-packages/jupyter_core/utils/__init__.py", line 165, in wrapped
    return loop.run_until_complete(inner)
           ^^^^^^^^^^^^^^^^^^^^^^^^^^^^^^
  File "/home/users/jaeminoh/.conda/envs/PINNs/lib/python3.12/asyncio/base_events.py", line 687, in run_until_complete
    return future.result()
           ^^^^^^^^^^^^^^^
  File "/home/users/jaeminoh/.conda/envs/PINNs/lib/python3.12/site-packages/nbclient/client.py", line 709, in async_execute
    await self.async_execute_cell(
  File "/home/users/jaeminoh/.conda/envs/PINNs/lib/python3.12/site-packages/nbclient/client.py", line 1062, in async_execute_cell
    await self._check_raise_for_error(cell, cell_index, exec_reply)
  File "/home/users/jaeminoh/.conda/envs/PINNs/lib/python3.12/site-packages/nbclient/client.py", line 918, in _check_raise_for_error
    raise CellExecutionError.from_cell_and_msg(cell, exec_reply_content)
nbclient.exceptions.CellExecutionError: An error occurred while executing the following cell:
------------------
f_fwd = jax.jit(f_fwd) # compile
f_fwd() # warmup
%timeit f_fwd().block_until_ready()
------------------


[0;31m---------------------------------------------------------------------------[0m
[0;31mValueError[0m                                Traceback (most recent call last)
Cell [0;32mIn[3], line 2[0m
[1;32m      1[0m f_fwd [38;5;241m=[39m jax[38;5;241m.[39mjit(f_fwd) [38;5;66;03m# compile[39;00m
[0;32m----> 2[0m [43mf_fwd[49m[43m([49m[43m)[49m [38;5;66;03m# warmup[39;00m
[1;32m      3[0m get_ipython()[38;5;241m.[39mrun_line_magic([38;5;124m'[39m[38;5;124mtimeit[39m[38;5;124m'[39m, [38;5;124m'[39m[38;5;124mf_fwd().block_until_ready()[39m[38;5;124m'[39m)

    [0;31m[... skipping hidden 13 frame][0m

File [0;32m~/.conda/envs/PINNs/lib/python3.12/site-packages/jax/_src/api_util.py:247[0m, in [0;36m_ensure_inbounds[0;34m(allow_invalid, num_args, argnums)[0m
[1;32m    245[0m   [38;5;28;01mif[39;00m i [38;5;241m>[39m[38;5;241m=[39m num_args [38;5;129;01mand[39;00m allow_invalid: [38;5;28;01mcontinue[39;00m
[1;32m    246[0m   [38;5;28;01mif[39;00m [38;5;129;01mnot[39;00m [38;5;241m-[39mnum_args [38;5;241m<[39m[38;5;241m=[39m i [38;5;241m<[39m num_args:
[0;32m--> 247[0m     [38;5;28;01mraise[39;00m [38;5;167;01mValueError[39;00m(
[1;32m    248[0m         [38;5;124m"[39m[38;5;124mPositional argument indices, e.g. for `static_argnums`, must have [39m[38;5;124m"[39m
[1;32m    249[0m         [38;5;124m"[39m[38;5;124mvalue greater than or equal to -len(args) and less than len(args), [39m[38;5;124m"[39m
[1;32m    250[0m         [38;5;124mf[39m[38;5;124m"[39m[38;5;124mbut got value [39m[38;5;132;01m{[39;00mi[38;5;132;01m}[39;00m[38;5;124m for len(args) == [39m[38;5;132;01m{[39;00mnum_args[38;5;132;01m}[39;00m[38;5;124m.[39m[38;5;124m"[39m)
[1;32m    251[0m   result[38;5;241m.[39mappend(i [38;5;241m%[39m num_args)  [38;5;66;03m# Resolve negative[39;00m
[1;32m    252[0m [38;5;28;01mreturn[39;00m [38;5;28mtuple[39m(result)

[0;31mValueError[0m: Positional argument indices, e.g. for `static_argnums`, must have value greater than or equal to -len(args) and less than len(args), but got value 0 for len(args) == 0.

